[2020-04-21T17:46:38Z] DEBUG    - Logging set up successfully
[2020-04-21T17:46:38Z] DEBUG    - Running generate: Namespace(command=<function generate at 0x10ed7aa70>, subparser_name='generate', verbose=0, version=False)
[2020-04-21T17:46:38Z] DEBUG    - Root directory: /Users/haithamg/Workspaces/GitHub/resource-providers-macie
[2020-04-21T17:46:38Z] DEBUG    - Loading project file '/Users/haithamg/Workspaces/GitHub/resource-providers-macie/.rpdk-config'
[2020-04-21T17:46:38Z] DEBUG    - Project file not found. Have you run 'init'?
Traceback (most recent call last):
  File "/usr/local/lib/python3.7/site-packages/rpdk/core/project.py", line 275, in load
    self.load_settings()
  File "/usr/local/lib/python3.7/site-packages/rpdk/core/project.py", line 126, in load_settings
    with self.settings_path.open("r", encoding="utf-8") as f:
  File "/usr/local/Cellar/python/3.7.7/Frameworks/Python.framework/Versions/3.7/lib/python3.7/pathlib.py", line 1203, in open
    opener=self._opener)
  File "/usr/local/Cellar/python/3.7.7/Frameworks/Python.framework/Versions/3.7/lib/python3.7/pathlib.py", line 1058, in _opener
    return self._accessor.open(self, flags, mode)
FileNotFoundError: [Errno 2] No such file or directory: '/Users/haithamg/Workspaces/GitHub/resource-providers-macie/.rpdk-config'
[2020-04-21T17:46:38Z] DEBUG    - Caught exit recommendation
Traceback (most recent call last):
  File "/usr/local/lib/python3.7/site-packages/rpdk/core/project.py", line 275, in load
    self.load_settings()
  File "/usr/local/lib/python3.7/site-packages/rpdk/core/project.py", line 126, in load_settings
    with self.settings_path.open("r", encoding="utf-8") as f:
  File "/usr/local/Cellar/python/3.7.7/Frameworks/Python.framework/Versions/3.7/lib/python3.7/pathlib.py", line 1203, in open
    opener=self._opener)
  File "/usr/local/Cellar/python/3.7.7/Frameworks/Python.framework/Versions/3.7/lib/python3.7/pathlib.py", line 1058, in _opener
    return self._accessor.open(self, flags, mode)
FileNotFoundError: [Errno 2] No such file or directory: '/Users/haithamg/Workspaces/GitHub/resource-providers-macie/.rpdk-config'

The above exception was the direct cause of the following exception:

Traceback (most recent call last):
  File "/usr/local/lib/python3.7/site-packages/rpdk/core/cli.py", line 98, in main
    args.command(args)
  File "/usr/local/lib/python3.7/site-packages/rpdk/core/generate.py", line 14, in generate
    project.load()
  File "/usr/local/lib/python3.7/site-packages/rpdk/core/project.py", line 278, in load
    "Project file not found. Have you run 'init'?", e
  File "/usr/local/lib/python3.7/site-packages/rpdk/core/project.py", line 121, in _raise_invalid_project
    raise InvalidProjectError(msg) from e
rpdk.core.exceptions.InvalidProjectError: Project file not found. Have you run 'init'?
[2020-04-21T17:46:38Z] CRITICAL - Project file not found. Have you run 'init'?
